# AraHaul Experiment #1: [Aviat Link Configuration and Status Check](https://arawireless.readthedocs.io/en/latest/ara_experiments/arahaul_experiments/aviat_status_check.html#arahaul-experiment-link-configuration)

### Configure SSH on ARA JumpBox to disable HostKeyChecking
```
mkandes@hardtack:~$ ssh ara
mckandes@ara-jbox:~$ cat .ssh/config 
Host *
ServerAliveInterval 60
ServerAliveCountMax 2
StrictHostKeyChecking no
UserKnownHostsFile /dev/null
LogLevel QUIET
mckandes@ara-jbox:~$
```
### [Checking the Status of Link/Radio](https://arawireless.readthedocs.io/en/latest/ara_experiments/arahaul_experiments/aviat_status_check.html#checking-the-status-of-link-radio)

*Command*
```
aviatcli carrier show capabilities Carrier1/1
```

*Output*
```
root@WilsonHallAviat:~# aviatcli carrier show capabilities Carrier1/1
Traceback (most recent call last):

  File "/usr/local/lib/python3.10/site-packages/urllib3/connection.py", line 203, in _new_conn
    sock = connection.create_connection(

  File "/usr/local/lib/python3.10/site-packages/urllib3/util/connection.py", line 85, in create_connection
    raise err

  File "/usr/local/lib/python3.10/site-packages/urllib3/util/connection.py", line 73, in create_connection
    sock.connect(sa)

ConnectionRefusedError: [Errno 111] Connection refused


The above exception was the direct cause of the following exception:


Traceback (most recent call last):

  File "/usr/local/lib/python3.10/site-packages/urllib3/connectionpool.py", line 790, in urlopen
    response = self._make_request(

  File "/usr/local/lib/python3.10/site-packages/urllib3/connectionpool.py", line 496, in _make_request
    conn.request(

  File "/usr/local/lib/python3.10/site-packages/urllib3/connection.py", line 395, in request
    self.endheaders()

  File "/usr/local/lib/python3.10/http/client.py", line 1278, in endheaders
    self._send_output(message_body, encode_chunked=encode_chunked)

  File "/usr/local/lib/python3.10/http/client.py", line 1038, in _send_output
    self.send(msg)

  File "/usr/local/lib/python3.10/http/client.py", line 976, in send
    self.connect()

  File "/usr/local/lib/python3.10/site-packages/urllib3/connection.py", line 243, in connect
    self.sock = self._new_conn()

  File "/usr/local/lib/python3.10/site-packages/urllib3/connection.py", line 218, in _new_conn
    raise NewConnectionError(

urllib3.exceptions.NewConnectionError: <urllib3.connection.HTTPConnection object at 0x7f6fb0257c70>: Failed to establish a new connection: [Errno 111] Connection refused


The above exception was the direct cause of the following exception:


Traceback (most recent call last):

  File "/usr/local/lib/python3.10/site-packages/requests/adapters.py", line 486, in send
    resp = conn.urlopen(

  File "/usr/local/lib/python3.10/site-packages/urllib3/connectionpool.py", line 844, in urlopen
    retries = retries.increment(

  File "/usr/local/lib/python3.10/site-packages/urllib3/util/retry.py", line 515, in increment
    raise MaxRetryError(_pool, url, reason) from reason  # type: ignore[arg-type]

urllib3.exceptions.MaxRetryError: HTTPConnectionPool(host='10.188.0.131', port=5001): Max retries exceeded with url: /Measurement/Carrier11Capabilities (Caused by NewConnectionError('<urllib3.connection.HTTPConnection object at 0x7f6fb0257c70>: Failed to establish a new connection: [Errno 111] Connection refused'))


During handling of the above exception, another exception occurred:


Traceback (most recent call last):

  File "/usr/local/bin/aviatcli", line 8, in <module>
    sys.exit(main())

  File "/usr/local/lib/python3.10/site-packages/aviat_cli/__main__.py", line 7, in main
    app(prog_name=__app_name__)

  File "/usr/local/lib/python3.10/site-packages/aviat_cli/commands/carrier/show.py", line 31, in check_capabilities
    response = get_carrier11_capabilities(remote)

  File "/usr/local/lib/python3.10/site-packages/aviat_client/get_requests.py", line 18, in get_carrier11_capabilities
    response = get(url)

  File "/usr/local/lib/python3.10/site-packages/requests/api.py", line 73, in get
    return request("get", url, params=params, **kwargs)

  File "/usr/local/lib/python3.10/site-packages/requests/api.py", line 59, in request
    return session.request(method=method, url=url, **kwargs)

  File "/usr/local/lib/python3.10/site-packages/requests/sessions.py", line 589, in request
    resp = self.send(prep, **send_kwargs)

  File "/usr/local/lib/python3.10/site-packages/requests/sessions.py", line 703, in send
    r = adapter.send(request, **kwargs)

  File "/usr/local/lib/python3.10/site-packages/requests/adapters.py", line 519, in send
    raise ConnectionError(e, request=request)

requests.exceptions.ConnectionError: HTTPConnectionPool(host='10.188.0.131', port=5001): Max retries exceeded with url: /Measurement/Carrier11Capabilities (Caused by NewConnectionError('<urllib3.connection.HTTPConnection object at 0x7f6fb0257c70>: Failed to establish a new connection: [Errno 111] Connection refused'))

root@WilsonHallAviat:~#
```
